Workbook

Sheet Comparativo
A1: INDUSTRIA SCHUMACHER LTDA
A2: Demonstração do Resultado do Exercício (DRE) – Comparativo mensal
A3: Período: 01/01/2026 a 31/08/2026 (valores mensais) | Filial: CONSOLIDADO
A4: CNPJ: 04.589.817/0001-06
A5: Valores em R$ (reais). Fonte: relatório do sistema contábil (PDF), convertido sem alteração de valores.
A7: Conta | B7: Jan/26 | C7: Fev/26 | D7: Mar/26 | E7: Abr/26 | F7: Mai/26 | G7: Jun/26 | H7: Jul/26 | I7: Ago/26 | J7: Acumulado Jan–Ago
A8: RECEITA OPERACIONAL BRUTA | B8: ='Jan-26'!B8 -> 65256171 | C8: ='Fev-26'!B8 -> 4421800.7 | D8: ='Mar-26'!B8 -> 5895674.1 | E8: ='Abr-26'!B8 -> 4724378.4 | F8: ='Mai-26'!B8 -> 4982409 | G8: ='Jun-26'!B8 -> 5521005 | H8: ='Jul-26'!B8 -> 5702251 | I8: ='Ago-26'!B8 -> 5448307.6 | J8: =SUM(B8:I8) -> 1.01952e+08
A9: RECEITAS DE VENDAS | B9: ='Jan-26'!B9 -> 66077106 | C9: ='Fev-26'!B9 -> 4726850.5 | D9: ='Mar-26'!B9 -> 6009654.5 | E9: ='Abr-26'!B9 -> 4736464.6 | F9: ='Mai-26'!B9 -> 4698899.2 | G9: ='Jun-26'!B9 -> 6249304.5 | H9: ='Jul-26'!B9 -> 5895604.8 | I9: ='Ago-26'!B9 -> 5683386 | J9: =SUM(B9:I9) -> 1.0407727e+08
A10: VENDAS MERCADO INTERNO | B10: ='Jan-26'!B10 -> 66077106 | C10: ='Fev-26'!B10 -> 4726850.5 | D10: ='Mar-26'!B10 -> 6009654.5 | E10: ='Abr-26'!B10 -> 4736464.6 | F10: ='Mai-26'!B10 -> 4698899.2 | G10: ='Jun-26'!B10 -> 6249304.5 | H10: ='Jul-26'!B10 -> 5895604.8 | I10: ='Ago-26'!B10 -> 5683386 | J10: =SUM(B10:I10) -> 1.0407727e+08
A11: VENDA PROD. IND. EM OP. CONTA PROPRIA (RESULTADO) | B11: ='Jan-26'!B11 -> 36324920 | C11: ='Fev-26'!B11 -> 4710051 | D11: ='Mar-26'!B11 -> 5991540.5 | E11: ='Abr-26'!B11 -> 4715511.1 | F11: ='Mai-26'!B11 -> 4682776.2 | G11: ='Jun-26'!B11 -> 6235791.5 | H11: ='Jul-26'!B11 -> 5863520.3 | I11: ='Ago-26'!B11 -> 5667516.5 | J11: =SUM(B11:I11) -> 74191627
A12: FATURAMENTO CFE. DL1598/77 ART.12 ITEM I | B12: ='Jan-26'!B12 -> 29520870 | J12: =SUM(B12:I12) -> 29520870
A13: VENDA DE SUCATA/ RESIDUO/ RECICLADOS | B13: ='Jan-26'!B13 -> 231315.75 | C13: ='Fev-26'!B12 -> 16799.41 | D13: ='Mar-26'!B12 -> 18114 | E13: ='Abr-26'!B12 -> 20953.49 | F13: ='Mai-26'!B12 -> 16123 | G13: ='Jun-26'!B12 -> 13513 | H13: ='Jul-26'!B12 -> 32084.5 | I13: ='Ago-26'!B12 -> 15869.6 | J13: =SUM(B13:I13) -> 364772.75
A14: VENDAS MERCADO EXTERNO | B14: ='Jan-26'!B14 -> 7093786.6 | C14: ='Fev-26'!B13 -> 211332.15 | D14: ='Mar-26'!B13 -> 714871.99 | E14: ='Abr-26'!B13 -> 605033.01 | F14: ='Mai-26'!B13 -> 720828.08 | G14: ='Jun-26'!B13 -> 462652.85 | H14: ='Jul-26'!B13 -> 390744.11 | I14: ='Ago-26'!B13 -> 308252.92 | J14: =SUM(B14:I14) -> 10507502
A15: VENDA DESTINADA A EXPORTACAO | B15: ='Jan-26'!B15 -> 2527913.2 | C15: ='Fev-26'!B14 -> 199345.15 | D15: ='Mar-26'!B14 -> 185945.39 | E15: ='Abr-26'!B14 -> 237498.65 | F15: ='Mai-26'!B14 -> 104523.32 | G15: ='Jun-26'!B14 -> 322203.11 | H15: ='Jul-26'!B14 -> 42378.34 | I15: ='Ago-26'!B14 -> 268734.72 | J15: =SUM(B15:I15) -> 3888541.9
A16: EXPORTACAO PROPRIA | B16: ='Jan-26'!B16 -> 4475893.3 | C16: ='Fev-26'!B15 -> 11987 | D16: ='Mar-26'!B15 -> 528926.6 | E16: ='Abr-26'!B15 -> 367534.36 | F16: ='Mai-26'!B15 -> 616304.76 | G16: ='Jun-26'!B15 -> 140449.74 | H16: ='Jul-26'!B15 -> 348365.77 | I16: ='Ago-26'!B15 -> 39518.2 | J16: =SUM(B16:I16) -> 6528979.8
A17: VENDA PRA DRAWBACK | B17: ='Jan-26'!B17 -> 5265 | J17: =SUM(B17:I17) -> 5265
A18: VENDA PROD. CONSIGNADO DEST. A EXPORTACAO | B18: ='Jan-26'!B18 -> 84715.1 | J18: =SUM(B18:I18) -> 84715.1
A19: SERVIÇOS MERCADO INTERNO | B19: ='Jan-26'!B19 -> 3083029.6 | C19: ='Fev-26'!B16 -> 189429.19 | D19: ='Mar-26'!B16 -> 292393.44 | E19: ='Abr-26'!B16 -> 324413.42 | F19: ='Mai-26'!B16 -> 323104.2 | G19: ='Jun-26'!B16 -> 425153.82 | H19: ='Jul-26'!B16 -> 350984.55 | I19: ='Ago-26'!B16 -> 370038.22 | J19: =SUM(B19:I19) -> 5358546.4
A20: INDUSTRIALIZACAO EFETUADA A TERCEIROS | B20: ='Jan-26'!B20 -> 2617837.2 | C20: ='Fev-26'!B17 -> 152965.49 | D20: ='Mar-26'!B17 -> 168743.86 | E20: ='Abr-26'!B17 -> 214665.07 | F20: ='Mai-26'!B17 -> 194366.82 | G20: ='Jun-26'!B17 -> 270329.01 | H20: ='Jul-26'!B17 -> 203764.46 | I20: ='Ago-26'!B17 -> 234613.03 | J20: =SUM(B20:I20) -> 4057284.9
A21: PRESTACAO DE SERVICOS | B21: ='Jan-26'!B21 -> 465192.39 | C21: ='Fev-26'!B18 -> 36463.7 | D21: ='Mar-26'!B18 -> 123649.58 | E21: ='Abr-26'!B18 -> 109748.35 | F21: ='Mai-26'!B18 -> 128737.38 | G21: ='Jun-26'!B18 -> 154824.81 | H21: ='Jul-26'!B18 -> 147220.09 | I21: ='Ago-26'!B18 -> 135425.19 | J21: =SUM(B21:I21) -> 1301261.5
A22: (-) IMPOSTOS SOBRE VENDAS | B22: ='Jan-26'!B22 -> 10997751 | C22: ='Fev-26'!B19 -> 705811.06 | D22: ='Mar-26'!B19 -> 1121245.9 | E22: ='Abr-26'!B19 -> 941532.59 | F22: ='Mai-26'!B19 -> 760422.52 | G22: ='Jun-26'!B19 -> 1616106.2 | H22: ='Jul-26'!B19 -> 935082.47 | I22: ='Ago-26'!B19 -> 913369.58 | J22: =SUM(B22:I22) -> 17991321
A23: IPI S/ VENDAS | B23: ='Jan-26'!B23 -> 486086.4 | C23: ='Fev-26'!B20 -> 35801.85 | D23: ='Mar-26'!B20 -> 39340.04 | E23: ='Abr-26'!B20 -> 27921.59 | F23: ='Mai-26'!B20 -> 34455.93 | G23: ='Jun-26'!B20 -> 41102.4 | H23: ='Jul-26'!B20 -> 39049.03 | I23: ='Ago-26'!B20 -> 41557.42 | J23: =SUM(B23:I23) -> 745314.66
A24: ICMS S/ VENDAS | B24: ='Jan-26'!B24 -> 7816591.2 | C24: ='Fev-26'!B21 -> 562883.31 | D24: ='Mar-26'!B21 -> 709755.95 | E24: ='Abr-26'!B21 -> 742405.23 | F24: ='Mai-26'!B21 -> 545460.16 | G24: ='Jun-26'!B21 -> 807399.58 | H24: ='Jul-26'!B21 -> 691676.03 | I24: ='Ago-26'!B21 -> 669571.08 | J24: =SUM(B24:I24) -> 12545743
A25: PIS S/ VENDAS | B25: ='Jan-26'!B25 -> 244816.06 | C25: ='Fev-26'!B22 -> 15080.93 | D25: ='Mar-26'!B22 -> 18368.97 | E25: ='Abr-26'!B22 -> 26434 | F25: ='Mai-26'!B22 -> 26300.24 | G25: ='Jun-26'!B22 -> 33146.27 | H25: ='Jul-26'!B22 -> 30270.24 | I25: ='Ago-26'!B22 -> 30453.6 | J25: =SUM(B25:I25) -> 424870.31
A26: COFINS S/ VENDAS | B26: ='Jan-26'!B26 -> 1124298.7 | C26: ='Fev-26'!B23 -> 69604.27 | D26: ='Mar-26'!B23 -> 84795.93 | E26: ='Abr-26'!B23 -> 122002.84 | F26: ='Mai-26'!B23 -> 121387.11 | G26: ='Jun-26'!B23 -> 152982.81 | H26: ='Jul-26'!B23 -> 139437.49 | I26: ='Ago-26'!B23 -> 140251.49 | J26: =SUM(B26:I26) -> 1954760.7
A27: ISSQN S/ SERVICOS | B27: ='Jan-26'!B27 -> 13955.84 | C27: ='Fev-26'!B24 -> 1093.89 | D27: ='Mar-26'!B24 -> 3709.48 | E27: ='Abr-26'!B24 -> 3292.44 | F27: ='Mai-26'!B24 -> 3862.14 | G27: ='Jun-26'!B24 -> 4644.74 | H27: ='Jul-26'!B24 -> 4416.6 | I27: ='Ago-26'!B24 -> 4062.76 | J27: =SUM(B27:I27) -> 39037.89
A28: ICMS-ST S/ VENDAS | B28: ='Jan-26'!B28 -> 252215.84 | C28: ='Fev-26'!B25 -> 21186.4 | D28: ='Mar-26'!B25 -> 23751.57 | E28: ='Abr-26'!B25 -> 19437.86 | F28: ='Mai-26'!B25 -> 28674.19 | G28: ='Jun-26'!B25 -> 25831.69 | H28: ='Jul-26'!B25 -> 29946.95 | I28: ='Ago-26'!B25 -> 27473.23 | J28: =SUM(B28:I28) -> 428517.73
A29: ICMS DIFAL SOBRE AS VENDAS | B29: ='Jan-26'!B29 -> 1082.44 | C29: ='Fev-26'!B26 -> 160.41 | D29: ='Mar-26'!B26 -> 142.28 | E29: ='Abr-26'!B26 -> 38.63 | F29: ='Mai-26'!B26 -> 282.75 | G29: ='Jun-26'!B26 -> 453.21 | H29: ='Jul-26'!B26 -> 286.13 | J29: =SUM(B29:I29) -> 2445.85
A30: IRPJ RETIDO S/ VENDAS | B30: ='Jan-26'!B30 -> 680737.75 | D30: ='Mar-26'!B27 -> 159103.54 | G30: ='Jun-26'!B27 -> 327175.48 | J30: =SUM(B30:I30) -> 1167016.8
A31: CSLL RETIDO S/ VENDAS | B31: ='Jan-26'!B31 -> 377966.39 | D31: ='Mar-26'!B28 -> 82278.1 | G31: ='Jun-26'!B28 -> 223369.99 | J31: =SUM(B31:I31) -> 683614.48
A32: DEDUÇÕES DA RECEITA BRUTA | B32: ='Jan-26'!B32 -> -445730.17 | C32: ='Fev-26'!B27 -> -45725.46 | D32: ='Mar-26'!B29 -> -2385.15 | E32: ='Abr-26'!B27 -> -9701.07 | F32: ='Mai-26'!B27 -> -2190.96 | G32: ='Jun-26'!B29 -> -864.34 | H32: ='Jul-26'!B27 -> -4009.96 | I32: ='Ago-26'!B26 -> -1527.21 | J32: =SUM(B32:I32) -> -512134.32
A33: (-) DEDUCOES DAS VENDAS | B33: ='Jan-26'!B33 -> 445730.17 | C33: ='Fev-26'!B28 -> 45725.46 | D33: ='Mar-26'!B30 -> 2385.15 | E33: ='Abr-26'!B28 -> 9701.07 | F33: ='Mai-26'!B28 -> 2190.96 | G33: ='Jun-26'!B30 -> 864.34 | H33: ='Jul-26'!B28 -> 4009.96 | I33: ='Ago-26'!B27 -> 1527.21 | J33: =SUM(B33:I33) -> 512134.32
A34: (-) CANCELAMENTOS E DEVOLUCOES | B34: ='Jan-26'!B34 -> 445730.17 | C34: ='Fev-26'!B29 -> 45725.46 | D34: ='Mar-26'!B31 -> 2385.15 | E34: ='Abr-26'!B29 -> 9701.07 | F34: ='Mai-26'!B29 -> 2190.96 | G34: ='Jun-26'!B31 -> 864.34 | H34: ='Jul-26'!B29 -> 4009.96 | I34: ='Ago-26'!B28 -> 1527.21 | J34: =SUM(B34:I34) -> 512134.32
A35: VENDAS CANCELADAS/ESTORNADAS | B35: ='Jan-26'!B35 -> 303435.11 | C35: ='Fev-26'!B30 -> 42575.8 | E35: ='Abr-26'!B30 -> 4389.57 | F35: ='Mai-26'!B30 -> 1315.14 | H35: ='Jul-26'!B30 -> 1338.6 | J35: =SUM(B35:I35) -> 353054.22
A36: EXPORTACAO CANCELADA/ DEVOLVIDA | B36: ='Jan-26'!B36 -> 6939 | J36: =SUM(B36:I36) -> 6939
A37: DEVOLUCAO DE VENDAS | B37: ='Jan-26'!B37 -> 101572.91 | C37: ='Fev-26'!B31 -> 3149.66 | D37: ='Mar-26'!B32 -> 2385.15 | E37: ='Abr-26'!B31 -> 5311.5 | F37: ='Mai-26'!B31 -> 875.82 | G37: ='Jun-26'!B32 -> 864.34 | H37: ='Jul-26'!B31 -> 2671.36 | I37: ='Ago-26'!B29 -> 1527.21 | J37: =SUM(B37:I37) -> 118357.95
A38: (-) CANCELAMENTO DE INDUSTRIALIZACAO | B38: ='Jan-26'!B38 -> 33783.15 | J38: =SUM(B38:I38) -> 33783.15
A39: RECEITA LÍQUIDA | B39: ='Jan-26'!B39 -> 64810441 | C39: ='Fev-26'!B32 -> 4376075.3 | D39: ='Mar-26'!B33 -> 5893289 | E39: ='Abr-26'!B32 -> 4714677.3 | F39: ='Mai-26'!B32 -> 4980218 | G39: ='Jun-26'!B33 -> 5520140.7 | H39: ='Jul-26'!B32 -> 5698241.1 | I39: ='Ago-26'!B30 -> 5446780.4 | J39: =SUM(B39:I39) -> 1.0143986e+08
A40: CUSTOS | B40: ='Jan-26'!B40 -> -43222401 | C40: ='Fev-26'!B33 -> -4756213.8 | D40: ='Mar-26'!B34 -> -7546765.7 | E40: ='Abr-26'!B33 -> -4933376 | F40: ='Mai-26'!B33 -> -5181524.7 | G40: ='Jun-26'!B34 -> -5538137.2 | H40: ='Jul-26'!B33 -> -4788917.3 | I40: ='Ago-26'!B31 -> -4398210.6 | J40: =SUM(B40:I40) -> -80365546
A41: CUSTOS DOS PRODUTOS VENDIDOS | B41: ='Jan-26'!B41 -> 43222401 | C41: ='Fev-26'!B34 -> 4756213.8 | D41: ='Mar-26'!B35 -> 7546765.7 | E41: ='Abr-26'!B34 -> 4933376 | F41: ='Mai-26'!B34 -> 5181524.7 | G41: ='Jun-26'!B35 -> 5538137.2 | H41: ='Jul-26'!B34 -> 4788917.3 | I41: ='Ago-26'!B32 -> 4398210.6 | J41: =SUM(B41:I41) -> 80365546
...

Sheet Jan-26
A1: INDUSTRIA SCHUMACHER LTDA
A2: Demonstração do Resultado do Exercício (DRE)
A3: Período: 01/01/2026 a 31/01/2026 | Filial: CONSOLIDADO
A4: CNPJ: 04.589.817/0001-06
A5: Valores em R$ (reais). Fonte: relatório do sistema contábil (PDF), convertido sem alteração de valores.
A7: Conta | B7: Valor (R$)
A8: RECEITA OPERACIONAL BRUTA | B8: 65256171
A9: RECEITAS DE VENDAS | B9: 66077106
A10: VENDAS MERCADO INTERNO | B10: 66077106
A11: VENDA PROD. IND. EM OP. CONTA PROPRIA (RESULTADO) | B11: 36324920
A12: FATURAMENTO CFE. DL1598/77 ART.12 ITEM I | B12: 29520870
A13: VENDA DE SUCATA/ RESIDUO/ RECICLADOS | B13: 231315.75
A14: VENDAS MERCADO EXTERNO | B14: 7093786.6
A15: VENDA DESTINADA A EXPORTACAO | B15: 2527913.2
A16: EXPORTACAO PROPRIA | B16: 4475893.3
A17: VENDA PRA DRAWBACK | B17: 5265
A18: VENDA PROD. CONSIGNADO DEST. A EXPORTACAO | B18: 84715.1
A19: SERVIÇOS MERCADO INTERNO | B19: 3083029.6
... A187: LUCRO OU PREJUIZO LÍQUIDO DO EXERCÍCIO | B187: 3286063.3
A189: MARECHAL CANDIDO RONDON, 31 de janeiro de 2026
A191: ADAIR SCHUMACHER | B191: PAULO HENRIQUE DIAS RODRIGUES
A192: C.P.F. Nº 90348664915 | B192: C.R.C Nº CRC/DF 27618/O
A193: SOCIO GERENTE | B193: CONTADOR(A)

Sheet Fev-26
A1: INDUSTRIA SCHUMACHER LTDA
A2: Demonstração do Resultado do Exercício (DRE)
A3: Período: 01/02/2026 a 28/02/2026 | Filial: CONSOLIDADO
A4: CNPJ: 04.589.817/0001-06
A5: Valores em R$ (reais). Fonte: relatório do sistema contábil (PDF), convertido sem alteração de valores.
A7: Conta | B7: Valor (R$)
A8: RECEITA OPERACIONAL BRUTA | B8: 4421800.7
A9: RECEITAS DE VENDAS | B9: 4726850.5
A10: VENDAS MERCADO INTERNO | B10: 4726850.5
A11: VENDA PROD. IND. EM OP. CONTA PROPRIA (RESULTADO) | B11: 4710051
A12: VENDA DE SUCATA/ RESIDUO/ RECICLADOS | B12: 16799.41
A13: VENDAS MERCADO EXTERNO | B13: 211332.15
A14: VENDA DESTINADA A EXPORTACAO | B14: 199345.15
A15: EXPORTACAO PROPRIA | B15: 11987
A16: SERVIÇOS MERCADO INTERNO | B16: 189429.19
A17: INDUSTRIALIZACAO EFETUADA A TERCEIROS | B17: 152965.49
A18: PRESTACAO DE SERVICOS | B18: 36463.7
A19: (-) IMPOSTOS SOBRE VENDAS | B19: 705811.06
... A147: LUCRO OU PREJUIZO LÍQUIDO DO EXERCÍCIO | B147: -1242712.1
A149: MARECHAL CANDIDO RONDON, 28 de fevereiro de 2026
A151: ADAIR SCHUMACHER | B151: PAULO HENRIQUE DIAS RODRIGUES
A152: C.P.F. Nº 90348664915 | B152: C.R.C Nº CRC/DF 27618/O
A153: SOCIO GERENTE | B153: CONTADOR(A)

Sheet Mar-26
A1: INDUSTRIA SCHUMACHER LTDA
A2: Demonstração do Resultado do Exercício (DRE)
A3: Período: 01/03/2026 a 31/03/2026 | Filial: CONSOLIDADO
A4: CNPJ: 04.589.817/0001-06
A5: Valores em R$ (reais). Fonte: relatório do sistema contábil (PDF), convertido sem alteração de valores.
A7: Conta | B7: Valor (R$)
A8: RECEITA OPERACIONAL BRUTA | B8: 5895674.1
A9: RECEITAS DE VENDAS | B9: 6009654.5
A10: VENDAS MERCADO INTERNO | B10: 6009654.5
A11: VENDA PROD. IND. EM OP. CONTA PROPRIA (RESULTADO) | B11: 5991540.5
A12: VENDA DE SUCATA/ RESIDUO/ RECICLADOS | B12: 18114
A13: VENDAS MERCADO EXTERNO | B13: 714871.99
A14: VENDA DESTINADA A EXPORTACAO | B14: 185945.39
A15: EXPORTACAO PROPRIA | B15: 528926.6
A16: SERVIÇOS MERCADO INTERNO | B16: 292393.44
A17: INDUSTRIALIZACAO EFETUADA A TERCEIROS | B17: 168743.86
A18: PRESTACAO DE SERVICOS | B18: 123649.58
A19: (-) IMPOSTOS SOBRE VENDAS | B19: 1121245.9
... A157: LUCRO OU PREJUIZO LÍQUIDO DO EXERCÍCIO | B157: -2982381.6
A159: MARECHAL CANDIDO RONDON, 31 de março de 2026
A161: ADAIR SCHUMACHER | B161: PAULO HENRIQUE DIAS RODRIGUES
A162: C.P.F. Nº 90348664915 | B162: C.R.C Nº CRC/DF 27618/O
A163: SOCIO GERENTE | B163: CONTADOR(A)

Sheet Abr-26
A1: INDUSTRIA SCHUMACHER LTDA
A2: Demonstração do Resultado do Exercício (DRE)
A3: Período: 01/04/2026 a 30/04/2026 | Filial: CONSOLIDADO
A4: CNPJ: 04.589.817/0001-06
A5: Valores em R$ (reais). Fonte: relatório do sistema contábil (PDF), convertido sem alteração de valores.
A7: Conta | B7: Valor (R$)
A8: RECEITA OPERACIONAL BRUTA | B8: 4724378.4
A9: RECEITAS DE VENDAS | B9: 4736464.6
A10: VENDAS MERCADO INTERNO | B10: 4736464.6
A11: VENDA PROD. IND. EM OP. CONTA PROPRIA (RESULTADO) | B11: 4715511.1
A12: VENDA DE SUCATA/ RESIDUO/ RECICLADOS | B12: 20953.49
A13: VENDAS MERCADO EXTERNO | B13: 605033.01
A14: VENDA DESTINADA A EXPORTACAO | B14: 237498.65
A15: EXPORTACAO PROPRIA | B15: 367534.36
A16: SERVIÇOS MERCADO INTERNO | B16: 324413.42
A17: INDUSTRIALIZACAO EFETUADA A TERCEIROS | B17: 214665.07
A18: PRESTACAO DE SERVICOS | B18: 109748.35
A19: (-) IMPOSTOS SOBRE VENDAS | B19: 941532.59
... A155: LUCRO OU PREJUIZO LÍQUIDO DO EXERCÍCIO | B155: -1010496.9
A157: MARECHAL CANDIDO RONDON, 30 de abril de 2026
A159: ADAIR SCHUMACHER | B159: PAULO HENRIQUE DIAS RODRIGUES
A160: C.P.F. Nº 90348664915 | B160: C.R.C Nº CRC/DF 27618/O
A161: SOCIO GERENTE | B161: CONTADOR(A)

Sheet Mai-26
A1: INDUSTRIA SCHUMACHER LTDA
A2: Demonstração do Resultado do Exercício (DRE)
A3: Período: 01/05/2026 a 31/05/2026 | Filial: CONSOLIDADO
A4: CNPJ: 04.589.817/0001-06
A5: Valores em R$ (reais). Fonte: relatório do sistema contábil (PDF), convertido sem alteração de valores.
A7: Conta | B7: Valor (R$)
A8: RECEITA OPERACIONAL BRUTA | B8: 4982409
A9: RECEITAS DE VENDAS | B9: 4698899.2
A10: VENDAS MERCADO INTERNO | B10: 4698899.2
A11: VENDA PROD. IND. EM OP. CONTA PROPRIA (RESULTADO) | B11: 4682776.2
A12: VENDA DE SUCATA/ RESIDUO/ RECICLADOS | B12: 16123
A13: VENDAS MERCADO EXTERNO | B13: 720828.08
A14: VENDA DESTINADA A EXPORTACAO | B14: 104523.32
A15: EXPORTACAO PROPRIA | B15: 616304.76
A16: SERVIÇOS MERCADO INTERNO | B16: 323104.2
A17: INDUSTRIALIZACAO EFETUADA A TERCEIROS | B17: 194366.82
A18: PRESTACAO DE SERVICOS | B18: 128737.38
A19: (-) IMPOSTOS SOBRE VENDAS | B19: 760422.52
... A159: LUCRO OU PREJUIZO LÍQUIDO DO EXERCÍCIO | B159: -1117187.2
A161: MARECHAL CANDIDO RONDON, 31 de maio de 2026
A163: ADAIR SCHUMACHER | B163: PAULO HENRIQUE DIAS RODRIGUES
A164: C.P.F. Nº 90348664915 | B164: C.R.C Nº CRC/DF 27618/O
A165: SOCIO GERENTE | B165: CONTADOR(A)

Sheet Jun-26
A1: INDUSTRIA SCHUMACHER LTDA
A2: Demonstração do Resultado do Exercício (DRE)
A3: Período: 01/06/2026 a 30/06/2026 | Filial: CONSOLIDADO
A4: CNPJ: 04.589.817/0001-06
A5: Valores em R$ (reais). Fonte: relatório do sistema contábil (PDF), convertido sem alteração de valores.
A7: Conta | B7: Valor (R$)
A8: RECEITA OPERACIONAL BRUTA | B8: 5521005
A9: RECEITAS DE VENDAS | B9: 6249304.5
A10: VENDAS MERCADO INTERNO | B10: 6249304.5
A11: VENDA PROD. IND. EM OP. CONTA PROPRIA (RESULTADO) | B11: 6235791.5
A12: VENDA DE SUCATA/ RESIDUO/ RECICLADOS | B12: 13513
A13: VENDAS MERCADO EXTERNO | B13: 462652.85
A14: VENDA DESTINADA A EXPORTACAO | B14: 322203.11
A15: EXPORTACAO PROPRIA | B15: 140449.74
A16: SERVIÇOS MERCADO INTERNO | B16: 425153.82
A17: INDUSTRIALIZACAO EFETUADA A TERCEIROS | B17: 270329.01
A18: PRESTACAO DE SERVICOS | B18: 154824.81
A19: (-) IMPOSTOS SOBRE VENDAS | B19: 1616106.2
... A155: LUCRO OU PREJUIZO LÍQUIDO DO EXERCÍCIO | B155: -1131810.9
A157: MARECHAL CANDIDO RONDON, 30 de junho de 2026
A159: ADAIR SCHUMACHER | B159: PAULO HENRIQUE DIAS RODRIGUES
A160: C.P.F. Nº 90348664915 | B160: C.R.C Nº CRC/DF 27618/O
A161: SOCIO GERENTE | B161: CONTADOR(A)

Sheet Jul-26
A1: INDUSTRIA SCHUMACHER LTDA
A2: Demonstração do Resultado do Exercício (DRE)
A3: Período: 01/07/2026 a 31/07/2026 | Filial: CONSOLIDADO
A4: CNPJ: 04.589.817/0001-06
A5: Valores em R$ (reais). Fonte: relatório do sistema contábil (PDF), convertido sem alteração de valores.
A7: Conta | B7: Valor (R$)
A8: RECEITA OPERACIONAL BRUTA | B8: 5702251
A9: RECEITAS DE VENDAS | B9: 5895604.8
A10: VENDAS MERCADO INTERNO | B10: 5895604.8
A11: VENDA PROD. IND. EM OP. CONTA PROPRIA (RESULTADO) | B11: 5863520.3
A12: VENDA DE SUCATA/ RESIDUO/ RECICLADOS | B12: 32084.5
A13: VENDAS MERCADO EXTERNO | B13: 390744.11
A14: VENDA DESTINADA A EXPORTACAO | B14: 42378.34
A15: EXPORTACAO PROPRIA | B15: 348365.77
A16: SERVIÇOS MERCADO INTERNO | B16: 350984.55
A17: INDUSTRIALIZACAO EFETUADA A TERCEIROS | B17: 203764.46
A18: PRESTACAO DE SERVICOS | B18: 147220.09
A19: (-) IMPOSTOS SOBRE VENDAS | B19: 935082.47
... A150: LUCRO OU PREJUIZO LÍQUIDO DO EXERCÍCIO | B150: -512205.13
A152: MARECHAL CANDIDO RONDON, 31 de julho de 2026
A154: ADAIR SCHUMACHER | B154: PAULO HENRIQUE DIAS RODRIGUES
A155: C.P.F. Nº 90348664915 | B155: C.R.C Nº CRC/DF 27618/O
A156: SOCIO GERENTE | B156: CONTADOR(A)

Sheet Ago-26
A1: INDUSTRIA SCHUMACHER LTDA
A2: Demonstração do Resultado do Exercício (DRE)
A3: Período: 01/08/2026 a 31/08/2026 | Filial: CONSOLIDADO
A4: CNPJ: 04.589.817/0001-06
A5: Valores em R$ (reais). Fonte: relatório do sistema contábil (PDF), convertido sem alteração de valores.
A7: Conta | B7: Valor (R$)
A8: RECEITA OPERACIONAL BRUTA | B8: 5448307.6
A9: RECEITAS DE VENDAS | B9: 5683386
A10: VENDAS MERCADO INTERNO | B10: 5683386
A11: VENDA PROD. IND. EM OP. CONTA PROPRIA (RESULTADO) | B11: 5667516.5
A12: VENDA DE SUCATA/ RESIDUO/ RECICLADOS | B12: 15869.6
A13: VENDAS MERCADO EXTERNO | B13: 308252.92
A14: VENDA DESTINADA A EXPORTACAO | B14: 268734.72
A15: EXPORTACAO PROPRIA | B15: 39518.2
A16: SERVIÇOS MERCADO INTERNO | B16: 370038.22
A17: INDUSTRIALIZACAO EFETUADA A TERCEIROS | B17: 234613.03
A18: PRESTACAO DE SERVICOS | B18: 135425.19
A19: (-) IMPOSTOS SOBRE VENDAS | B19: 913369.58
... A152: LUCRO OU PREJUIZO LÍQUIDO DO EXERCÍCIO | B152: -60274.01
A154: MARECHAL CANDIDO RONDON, 31 de agosto de 2026
A156: ADAIR SCHUMACHER | B156: PAULO HENRIQUE DIAS RODRIGUES
A157: C.P.F. Nº 90348664915 | B157: C.R.C Nº CRC/DF 27618/O
A158: SOCIO GERENTE | B158: CONTADOR(A)
